# exception is an error
try: # try block
    x=6
    print(x)
except:
    print("An error occured")
finally:
    print("Success")